reported_result/report-9/ART_FClustering/output/output20.txt

Iceberg	1	3	6	3	1	SELL	0	---	0
NewOrderRs	Accepted
	Trades	0
	Orders	1
	Order	Iceberg	1	3	6	3	1	SELL	0	---	1
	Credits	7
	Credit	1	8
	Credit	2	17
	Credit	3	13
	Credit	4	13
	Credit	5	11
	Credit	6	10
	Credit	7	11
	Ownerships	7
	Ownership	1	88
	Ownership	2	82
	Ownership	3	51
	Ownership	4	90
	Ownership	5	78
	Ownership	6	62
	Ownership	7	47
	ReferencePrice	5
	StaticPriceBandLowerLimit	0.6
	StaticPriceBandUpperLimit	0.8
	TotalShares	100
	OwnershipUpperLimit	0.2
	TickSize	1
	LotSize	1
Limit	2	6	7	2	1	BUY 	1	---	0
NewOrderRs	Rejected
	Trades	0
	Orders	1
	Order	Iceberg	1	3	6	3	1	SELL	0	---	1
	Credits	7
	Credit	1	8
	Credit	2	17
	Credit	3	13
	Credit	4	13
	Credit	5	11
	Credit	6	10
	Credit	7	11
	Ownerships	7
	Ownership	1	88
	Ownership	2	82
	Ownership	3	51
	Ownership	4	90
	Ownership	5	78
	Ownership	6	62
	Ownership	7	47
	ReferencePrice	5
	StaticPriceBandLowerLimit	0.6
	StaticPriceBandUpperLimit	0.8
	TotalShares	100
	OwnershipUpperLimit	0.2
	TickSize	1
	LotSize	1
Iceberg	3	1	3	3	3	SELL	0	---	0
NewOrderRs	Accepted
	Trades	0
	Orders	2
	Order	Iceberg	1	3	6	3	1	SELL	0	---	1
	Order	Iceberg	3	1	3	3	3	SELL	0	---	2
	Credits	7
	Credit	1	8
	Credit	2	17
	Credit	3	13
	Credit	4	13
	Credit	5	11
	Credit	6	10
	Credit	7	11
	Ownerships	7
	Ownership	1	88
	Ownership	2	82
	Ownership	3	51
	Ownership	4	90
	Ownership	5	78
	Ownership	6	62
	Ownership	7	47
	ReferencePrice	5
	StaticPriceBandLowerLimit	0.6
	StaticPriceBandUpperLimit	0.8
	TotalShares	100
	OwnershipUpperLimit	0.2
	TickSize	1
	LotSize	1
Limit	4	5	2	8	1	SELL	0	---	0
NewOrderRs	Accepted
	Trades	0
	Orders	3
	Order	Iceberg	1	3	6	3	1	SELL	0	---	1
	Order	Iceberg	3	1	3	3	3	SELL	0	---	2
	Order	Limit	4	5	2	8	1	SELL	0	---	0
	Credits	7
	Credit	1	8
	Credit	2	17
	Credit	3	13
	Credit	4	13
	Credit	5	11
	Credit	6	10
	Credit	7	11
	Ownerships	7
	Ownership	1	88
	Ownership	2	82
	Ownership	3	51
	Ownership	4	90
	Ownership	5	78
	Ownership	6	62
	Ownership	7	47
	ReferencePrice	5
	StaticPriceBandLowerLimit	0.6
	StaticPriceBandUpperLimit	0.8
	TotalShares	100
	OwnershipUpperLimit	0.2
	TickSize	1
	LotSize	1
CancelOrderRs	Accepted
	Orders	2
	Order	Iceberg	1	3	6	3	1	SELL	0	---	1
	Order	Iceberg	3	1	3	3	3	SELL	0	---	2
	Credits	7
	Credit	1	8
	Credit	2	17
	Credit	3	13
	Credit	4	13
	Credit	5	11
	Credit	6	10
	Credit	7	11
	Ownerships	7
	Ownership	1	88
	Ownership	2	82
	Ownership	3	51
	Ownership	4	90
	Ownership	5	78
	Ownership	6	62
	Ownership	7	47
	ReferencePrice	5
	StaticPriceBandLowerLimit	0.6
	StaticPriceBandUpperLimit	0.8
	TotalShares	100
	OwnershipUpperLimit	0.2
	TickSize	1
	LotSize	1
Limit	6	5	4	7	4	BUY 	3	---	0
NewOrderRs	Rejected
	Trades	0
	Orders	2
	Order	Iceberg	1	3	6	3	1	SELL	0	---	1
	Order	Iceberg	3	1	3	3	3	SELL	0	---	2
	Credits	7
	Credit	1	8
	Credit	2	17
	Credit	3	13
	Credit	4	13
	Credit	5	11
	Credit	6	10
	Credit	7	11
	Ownerships	7
	Ownership	1	88
	Ownership	2	82
	Ownership	3	51
	Ownership	4	90
	Ownership	5	78
	Ownership	6	62
	Ownership	7	47
	ReferencePrice	5
	StaticPriceBandLowerLimit	0.6
	StaticPriceBandUpperLimit	0.8
	TotalShares	100
	OwnershipUpperLimit	0.2
	TickSize	1
	LotSize	1
Limit	7	3	1	2	1	SELL	0	---	0
NewOrderRs	Accepted
	Trades	0
	Orders	3
	Order	Limit	7	3	1	2	1	SELL	0	---	0
	Order	Iceberg	1	3	6	3	1	SELL	0	---	1
	Order	Iceberg	3	1	3	3	3	SELL	0	---	2
	Credits	7
	Credit	1	8
	Credit	2	17
	Credit	3	13
	Credit	4	13
	Credit	5	11
	Credit	6	10
	Credit	7	11
	Ownerships	7
	Ownership	1	88
	Ownership	2	82
	Ownership	3	51
	Ownership	4	90
	Ownership	5	78
	Ownership	6	62
	Ownership	7	47
	ReferencePrice	5
	StaticPriceBandLowerLimit	0.6
	StaticPriceBandUpperLimit	0.8
	TotalShares	100
	OwnershipUpperLimit	0.2
	TickSize	1
	LotSize	1
Limit	8	7	2	7	1	SELL	1	---	0
NewOrderRs	Eliminated
	Trades	0
	Orders	3
	Order	Limit	7	3	1	2	1	SELL	0	---	0
	Order	Iceberg	1	3	6	3	1	SELL	0	---	1
	Order	Iceberg	3	1	3	3	3	SELL	0	---	2
	Credits	7
	Credit	1	8
	Credit	2	17
	Credit	3	13
	Credit	4	13
	Credit	5	11
	Credit	6	10
	Credit	7	11
	Ownerships	7
	Ownership	1	88
	Ownership	2	82
	Ownership	3	51
	Ownership	4	90
	Ownership	5	78
	Ownership	6	62
	Ownership	7	47
	ReferencePrice	5
	StaticPriceBandLowerLimit	0.6
	StaticPriceBandUpperLimit	0.8
	TotalShares	100
	OwnershipUpperLimit	0.2
	TickSize	1
	LotSize	1
Limit	9	3	7	7	1	SELL	0	---	0
NewOrderRs	Accepted
	Trades	0
	Orders	4
	Order	Limit	7	3	1	2	1	SELL	0	---	0
	Order	Iceberg	1	3	6	3	1	SELL	0	---	1
	Order	Iceberg	3	1	3	3	3	SELL	0	---	2
	Order	Limit	9	3	7	7	1	SELL	0	---	0
	Credits	7
	Credit	1	8
	Credit	2	17
	Credit	3	13
	Credit	4	13
	Credit	5	11
	Credit	6	10
	Credit	7	11
	Ownerships	7
	Ownership	1	88
	Ownership	2	82
	Ownership	3	51
	Ownership	4	90
	Ownership	5	78
	Ownership	6	62
	Ownership	7	47
	ReferencePrice	5
	StaticPriceBandLowerLimit	0.6
	StaticPriceBandUpperLimit	0.8
	TotalShares	100
	OwnershipUpperLimit	0.2
	TickSize	1
	LotSize	1
Iceberg	10	3	7	5	8	SELL	0	---	0
ReplaceOrderRs	Accepted
	Trades	0
	Orders	4
	Order	Limit	7	3	1	2	1	SELL	0	---	0
	Order	Iceberg	1	3	6	3	1	SELL	0	---	1
	Order	Iceberg	3	1	3	3	3	SELL	0	---	2
	Order	Iceberg	10	3	7	5	8	SELL	0	---	4
	Credits	7
	Credit	1	8
	Credit	2	17
	Credit	3	13
	Credit	4	13
	Credit	5	11
	Credit	6	10
	Credit	7	11
	Ownerships	7
	Ownership	1	88
	Ownership	2	82
	Ownership	3	51
	Ownership	4	90
	Ownership	5	78
	Ownership	6	62
	Ownership	7	47
	ReferencePrice	5
	StaticPriceBandLowerLimit	0.6
	StaticPriceBandUpperLimit	0.8
	TotalShares	100
	OwnershipUpperLimit	0.2
	TickSize	1
	LotSize	1
