reported_result/report-9/ART_FT/output/output5.txt

Iceberg	1	3	2	6	4	SELL	0	---	0
NewOrderRs	Accepted
	Trades	0
	Orders	1
	Order	Iceberg	1	3	2	6	4	SELL	0	---	1
	Credits	7
	Credit	1	16
	Credit	2	10
	Credit	3	12
	Credit	4	17
	Credit	5	5
	Credit	6	7
	Credit	7	16
	Ownerships	7
	Ownership	1	42
	Ownership	2	69
	Ownership	3	28
	Ownership	4	62
	Ownership	5	73
	Ownership	6	28
	Ownership	7	38
	ReferencePrice	5
	StaticPriceBandLowerLimit	0.6
	StaticPriceBandUpperLimit	0.8
	TotalShares	100
	OwnershipUpperLimit	0.2
	TickSize	1
	LotSize	1
Limit	2	1	2	3	4	SELL	0	---	0
NewOrderRs	Accepted
	Trades	0
	Orders	2
	Order	Limit	2	1	2	3	4	SELL	0	---	0
	Order	Iceberg	1	3	2	6	4	SELL	0	---	1
	Credits	7
	Credit	1	16
	Credit	2	10
	Credit	3	12
	Credit	4	17
	Credit	5	5
	Credit	6	7
	Credit	7	16
	Ownerships	7
	Ownership	1	42
	Ownership	2	69
	Ownership	3	28
	Ownership	4	62
	Ownership	5	73
	Ownership	6	28
	Ownership	7	38
	ReferencePrice	5
	StaticPriceBandLowerLimit	0.6
	StaticPriceBandUpperLimit	0.8
	TotalShares	100
	OwnershipUpperLimit	0.2
	TickSize	1
	LotSize	1
Iceberg	3	6	6	7	6	SELL	4	---	0
NewOrderRs	Eliminated
	Trades	0
	Orders	2
	Order	Limit	2	1	2	3	4	SELL	0	---	0
	Order	Iceberg	1	3	2	6	4	SELL	0	---	1
	Credits	7
	Credit	1	16
	Credit	2	10
	Credit	3	12
	Credit	4	17
	Credit	5	5
	Credit	6	7
	Credit	7	16
	Ownerships	7
	Ownership	1	42
	Ownership	2	69
	Ownership	3	28
	Ownership	4	62
	Ownership	5	73
	Ownership	6	28
	Ownership	7	38
	ReferencePrice	5
	StaticPriceBandLowerLimit	0.6
	StaticPriceBandUpperLimit	0.8
	TotalShares	100
	OwnershipUpperLimit	0.2
	TickSize	1
	LotSize	1
Limit	4	2	6	2	8	BUY 	0	FAK	0
NewOrderRs	Rejected
	Trades	0
	Orders	2
	Order	Limit	2	1	2	3	4	SELL	0	---	0
	Order	Iceberg	1	3	2	6	4	SELL	0	---	1
	Credits	7
	Credit	1	16
	Credit	2	10
	Credit	3	12
	Credit	4	17
	Credit	5	5
	Credit	6	7
	Credit	7	16
	Ownerships	7
	Ownership	1	42
	Ownership	2	69
	Ownership	3	28
	Ownership	4	62
	Ownership	5	73
	Ownership	6	28
	Ownership	7	38
	ReferencePrice	5
	StaticPriceBandLowerLimit	0.6
	StaticPriceBandUpperLimit	0.8
	TotalShares	100
	OwnershipUpperLimit	0.2
	TickSize	1
	LotSize	1
CancelOrderRs	Rejected
	Orders	2
	Order	Limit	2	1	2	3	4	SELL	0	---	0
	Order	Iceberg	1	3	2	6	4	SELL	0	---	1
	Credits	7
	Credit	1	16
	Credit	2	10
	Credit	3	12
	Credit	4	17
	Credit	5	5
	Credit	6	7
	Credit	7	16
	Ownerships	7
	Ownership	1	42
	Ownership	2	69
	Ownership	3	28
	Ownership	4	62
	Ownership	5	73
	Ownership	6	28
	Ownership	7	38
	ReferencePrice	5
	StaticPriceBandLowerLimit	0.6
	StaticPriceBandUpperLimit	0.8
	TotalShares	100
	OwnershipUpperLimit	0.2
	TickSize	1
	LotSize	1
Iceberg	6	3	5	4	7	SELL	0	---	0
NewOrderRs	Accepted
	Trades	0
	Orders	3
	Order	Limit	2	1	2	3	4	SELL	0	---	0
	Order	Iceberg	6	3	5	4	7	SELL	0	---	7
	Order	Iceberg	1	3	2	6	4	SELL	0	---	1
	Credits	7
	Credit	1	16
	Credit	2	10
	Credit	3	12
	Credit	4	17
	Credit	5	5
	Credit	6	7
	Credit	7	16
	Ownerships	7
	Ownership	1	42
	Ownership	2	69
	Ownership	3	28
	Ownership	4	62
	Ownership	5	73
	Ownership	6	28
	Ownership	7	38
	ReferencePrice	5
	StaticPriceBandLowerLimit	0.6
	StaticPriceBandUpperLimit	0.8
	TotalShares	100
	OwnershipUpperLimit	0.2
	TickSize	1
	LotSize	1
Limit	7	5	3	5	1	SELL	0	FAK	0
NewOrderRs	Eliminated
	Trades	0
	Orders	3
	Order	Limit	2	1	2	3	4	SELL	0	---	0
	Order	Iceberg	6	3	5	4	7	SELL	0	---	7
	Order	Iceberg	1	3	2	6	4	SELL	0	---	1
	Credits	7
	Credit	1	16
	Credit	2	10
	Credit	3	12
	Credit	4	17
	Credit	5	5
	Credit	6	7
	Credit	7	16
	Ownerships	7
	Ownership	1	42
	Ownership	2	69
	Ownership	3	28
	Ownership	4	62
	Ownership	5	73
	Ownership	6	28
	Ownership	7	38
	ReferencePrice	5
	StaticPriceBandLowerLimit	0.6
	StaticPriceBandUpperLimit	0.8
	TotalShares	100
	OwnershipUpperLimit	0.2
	TickSize	1
	LotSize	1
Iceberg	8	6	5	6	1	BUY 	1	---	0
NewOrderRs	Rejected
	Trades	0
	Orders	3
	Order	Limit	2	1	2	3	4	SELL	0	---	0
	Order	Iceberg	6	3	5	4	7	SELL	0	---	7
	Order	Iceberg	1	3	2	6	4	SELL	0	---	1
	Credits	7
	Credit	1	16
	Credit	2	10
	Credit	3	12
	Credit	4	17
	Credit	5	5
	Credit	6	7
	Credit	7	16
	Ownerships	7
	Ownership	1	42
	Ownership	2	69
	Ownership	3	28
	Ownership	4	62
	Ownership	5	73
	Ownership	6	28
	Ownership	7	38
	ReferencePrice	5
	StaticPriceBandLowerLimit	0.6
	StaticPriceBandUpperLimit	0.8
	TotalShares	100
	OwnershipUpperLimit	0.2
	TickSize	1
	LotSize	1
Limit	9	6	3	4	7	SELL	7	---	0
NewOrderRs	Eliminated
	Trades	0
	Orders	3
	Order	Limit	2	1	2	3	4	SELL	0	---	0
	Order	Iceberg	6	3	5	4	7	SELL	0	---	7
	Order	Iceberg	1	3	2	6	4	SELL	0	---	1
	Credits	7
	Credit	1	16
	Credit	2	10
	Credit	3	12
	Credit	4	17
	Credit	5	5
	Credit	6	7
	Credit	7	16
	Ownerships	7
	Ownership	1	42
	Ownership	2	69
	Ownership	3	28
	Ownership	4	62
	Ownership	5	73
	Ownership	6	28
	Ownership	7	38
	ReferencePrice	5
	StaticPriceBandLowerLimit	0.6
	StaticPriceBandUpperLimit	0.8
	TotalShares	100
	OwnershipUpperLimit	0.2
	TickSize	1
	LotSize	1
Iceberg	10	6	3	10	4	SELL	0	---	0
ReplaceOrderRs	Rejected
	Trades	0
	Orders	3
	Order	Limit	2	1	2	3	4	SELL	0	---	0
	Order	Iceberg	6	3	5	4	7	SELL	0	---	7
	Order	Iceberg	1	3	2	6	4	SELL	0	---	1
	Credits	7
	Credit	1	16
	Credit	2	10
	Credit	3	12
	Credit	4	17
	Credit	5	5
	Credit	6	7
	Credit	7	16
	Ownerships	7
	Ownership	1	42
	Ownership	2	69
	Ownership	3	28
	Ownership	4	62
	Ownership	5	73
	Ownership	6	28
	Ownership	7	38
	ReferencePrice	5
	StaticPriceBandLowerLimit	0.6
	StaticPriceBandUpperLimit	0.8
	TotalShares	100
	OwnershipUpperLimit	0.2
	TickSize	1
	LotSize	1
Limit	11	6	6	6	2	BUY 	0	FAK	0
NewOrderRs	Rejected
	Trades	0
	Orders	3
	Order	Limit	2	1	2	3	4	SELL	0	---	0
	Order	Iceberg	6	3	5	4	7	SELL	0	---	7
	Order	Iceberg	1	3	2	6	4	SELL	0	---	1
	Credits	7
	Credit	1	16
	Credit	2	10
	Credit	3	12
	Credit	4	17
	Credit	5	5
	Credit	6	7
	Credit	7	16
	Ownerships	7
	Ownership	1	42
	Ownership	2	69
	Ownership	3	28
	Ownership	4	62
	Ownership	5	73
	Ownership	6	28
	Ownership	7	38
	ReferencePrice	5
	StaticPriceBandLowerLimit	0.6
	StaticPriceBandUpperLimit	0.8
	TotalShares	100
	OwnershipUpperLimit	0.2
	TickSize	1
	LotSize	1
Limit	12	7	1	1	5	BUY 	4	---	0
NewOrderRs	Rejected
	Trades	0
	Orders	3
	Order	Limit	2	1	2	3	4	SELL	0	---	0
	Order	Iceberg	6	3	5	4	7	SELL	0	---	7
	Order	Iceberg	1	3	2	6	4	SELL	0	---	1
	Credits	7
	Credit	1	16
	Credit	2	10
	Credit	3	12
	Credit	4	17
	Credit	5	5
	Credit	6	7
	Credit	7	16
	Ownerships	7
	Ownership	1	42
	Ownership	2	69
	Ownership	3	28
	Ownership	4	62
	Ownership	5	73
	Ownership	6	28
	Ownership	7	38
	ReferencePrice	5
	StaticPriceBandLowerLimit	0.6
	StaticPriceBandUpperLimit	0.8
	TotalShares	100
	OwnershipUpperLimit	0.2
	TickSize	1
	LotSize	1
Limit	13	5	4	2	1	SELL	0	---	0
NewOrderRs	Accepted
	Trades	0
	Orders	4
	Order	Limit	13	5	4	2	1	SELL	0	---	0
	Order	Limit	2	1	2	3	4	SELL	0	---	0
	Order	Iceberg	6	3	5	4	7	SELL	0	---	7
	Order	Iceberg	1	3	2	6	4	SELL	0	---	1
	Credits	7
	Credit	1	16
	Credit	2	10
	Credit	3	12
	Credit	4	17
	Credit	5	5
	Credit	6	7
	Credit	7	16
	Ownerships	7
	Ownership	1	42
	Ownership	2	69
	Ownership	3	28
	Ownership	4	62
	Ownership	5	73
	Ownership	6	28
	Ownership	7	38
	ReferencePrice	5
	StaticPriceBandLowerLimit	0.6
	StaticPriceBandUpperLimit	0.8
	TotalShares	100
	OwnershipUpperLimit	0.2
	TickSize	1
	LotSize	1
Iceberg	14	4	5	2	3	SELL	2	---	0
NewOrderRs	Eliminated
	Trades	0
	Orders	4
	Order	Limit	13	5	4	2	1	SELL	0	---	0
	Order	Limit	2	1	2	3	4	SELL	0	---	0
	Order	Iceberg	6	3	5	4	7	SELL	0	---	7
	Order	Iceberg	1	3	2	6	4	SELL	0	---	1
	Credits	7
	Credit	1	16
	Credit	2	10
	Credit	3	12
	Credit	4	17
	Credit	5	5
	Credit	6	7
	Credit	7	16
	Ownerships	7
	Ownership	1	42
	Ownership	2	69
	Ownership	3	28
	Ownership	4	62
	Ownership	5	73
	Ownership	6	28
	Ownership	7	38
	ReferencePrice	5
	StaticPriceBandLowerLimit	0.6
	StaticPriceBandUpperLimit	0.8
	TotalShares	100
	OwnershipUpperLimit	0.2
	TickSize	1
	LotSize	1
CancelOrderRs	Rejected
	Orders	4
	Order	Limit	13	5	4	2	1	SELL	0	---	0
	Order	Limit	2	1	2	3	4	SELL	0	---	0
	Order	Iceberg	6	3	5	4	7	SELL	0	---	7
	Order	Iceberg	1	3	2	6	4	SELL	0	---	1
	Credits	7
	Credit	1	16
	Credit	2	10
	Credit	3	12
	Credit	4	17
	Credit	5	5
	Credit	6	7
	Credit	7	16
	Ownerships	7
	Ownership	1	42
	Ownership	2	69
	Ownership	3	28
	Ownership	4	62
	Ownership	5	73
	Ownership	6	28
	Ownership	7	38
	ReferencePrice	5
	StaticPriceBandLowerLimit	0.6
