reported_result/report-9/ART_ISP/output/output2.txt

Limit	1	4	6	8	2	SELL	0	FAK	0
NewOrderRs	Eliminated
	Trades	0
	Orders	0
	Credits	7
	Credit	1	1
	Credit	2	3
	Credit	3	5
	Credit	4	4
	Credit	5	17
	Credit	6	13
	Credit	7	0
	Ownerships	7
	Ownership	1	12
	Ownership	2	58
	Ownership	3	62
	Ownership	4	12
	Ownership	5	31
	Ownership	6	12
	Ownership	7	35
	ReferencePrice	5
	StaticPriceBandLowerLimit	0.6
	StaticPriceBandUpperLimit	0.8
	TotalShares	100
	OwnershipUpperLimit	0.2
	TickSize	1
	LotSize	1
Limit	2	3	5	4	8	SELL	0	---	0
NewOrderRs	Accepted
	Trades	0
	Orders	1
	Order	Limit	2	3	5	4	8	SELL	0	---	0
	Credits	7
	Credit	1	1
	Credit	2	3
	Credit	3	5
	Credit	4	4
	Credit	5	17
	Credit	6	13
	Credit	7	0
	Ownerships	7
	Ownership	1	12
	Ownership	2	58
	Ownership	3	62
	Ownership	4	12
	Ownership	5	31
	Ownership	6	12
	Ownership	7	35
	ReferencePrice	5
	StaticPriceBandLowerLimit	0.6
	StaticPriceBandUpperLimit	0.8
	TotalShares	100
	OwnershipUpperLimit	0.2
	TickSize	1
	LotSize	1
Limit	3	3	2	6	7	SELL	0	---	0
NewOrderRs	Accepted
	Trades	0
	Orders	2
	Order	Limit	2	3	5	4	8	SELL	0	---	0
	Order	Limit	3	3	2	6	7	SELL	0	---	0
	Credits	7
	Credit	1	1
	Credit	2	3
	Credit	3	5
	Credit	4	4
	Credit	5	17
	Credit	6	13
	Credit	7	0
	Ownerships	7
	Ownership	1	12
	Ownership	2	58
	Ownership	3	62
	Ownership	4	12
	Ownership	5	31
	Ownership	6	12
	Ownership	7	35
	ReferencePrice	5
	StaticPriceBandLowerLimit	0.6
	StaticPriceBandUpperLimit	0.8
	TotalShares	100
	OwnershipUpperLimit	0.2
	TickSize	1
	LotSize	1
Limit	4	4	3	1	4	SELL	0	---	0
NewOrderRs	Rejected
	Trades	0
	Orders	2
	Order	Limit	2	3	5	4	8	SELL	0	---	0
	Order	Limit	3	3	2	6	7	SELL	0	---	0
	Credits	7
	Credit	1	1
	Credit	2	3
	Credit	3	5
	Credit	4	4
	Credit	5	17
	Credit	6	13
	Credit	7	0
	Ownerships	7
	Ownership	1	12
	Ownership	2	58
	Ownership	3	62
	Ownership	4	12
	Ownership	5	31
	Ownership	6	12
	Ownership	7	35
	ReferencePrice	5
	StaticPriceBandLowerLimit	0.6
	StaticPriceBandUpperLimit	0.8
	TotalShares	100
	OwnershipUpperLimit	0.2
	TickSize	1
	LotSize	1
CancelOrderRs	Rejected
	Orders	2
	Order	Limit	2	3	5	4	8	SELL	0	---	0
	Order	Limit	3	3	2	6	7	SELL	0	---	0
	Credits	7
	Credit	1	1
	Credit	2	3
	Credit	3	5
	Credit	4	4
	Credit	5	17
	Credit	6	13
	Credit	7	0
	Ownerships	7
	Ownership	1	12
	Ownership	2	58
	Ownership	3	62
	Ownership	4	12
	Ownership	5	31
	Ownership	6	12
	Ownership	7	35
	ReferencePrice	5
	StaticPriceBandLowerLimit	0.6
	StaticPriceBandUpperLimit	0.8
	TotalShares	100
	OwnershipUpperLimit	0.2
	TickSize	1
	LotSize	1
Limit	6	1	4	9	7	SELL	0	---	0
NewOrderRs	Accepted
	Trades	0
	Orders	3
	Order	Limit	2	3	5	4	8	SELL	0	---	0
	Order	Limit	3	3	2	6	7	SELL	0	---	0
	Order	Limit	6	1	4	9	7	SELL	0	---	0
	Credits	7
	Credit	1	1
	Credit	2	3
	Credit	3	5
	Credit	4	4
	Credit	5	17
	Credit	6	13
	Credit	7	0
	Ownerships	7
	Ownership	1	12
	Ownership	2	58
	Ownership	3	62
	Ownership	4	12
	Ownership	5	31
	Ownership	6	12
	Ownership	7	35
	ReferencePrice	5
	StaticPriceBandLowerLimit	0.6
	StaticPriceBandUpperLimit	0.8
	TotalShares	100
	OwnershipUpperLimit	0.2
	TickSize	1
	LotSize	1
Iceberg	7	1	7	10	1	BUY 	1	---	0
NewOrderRs	Rejected
	Trades	0
	Orders	3
	Order	Limit	2	3	5	4	8	SELL	0	---	0
	Order	Limit	3	3	2	6	7	SELL	0	---	0
	Order	Limit	6	1	4	9	7	SELL	0	---	0
	Credits	7
	Credit	1	1
	Credit	2	3
	Credit	3	5
	Credit	4	4
	Credit	5	17
	Credit	6	13
	Credit	7	0
	Ownerships	7
	Ownership	1	12
	Ownership	2	58
	Ownership	3	62
	Ownership	4	12
	Ownership	5	31
	Ownership	6	12
	Ownership	7	35
	ReferencePrice	5
	StaticPriceBandLowerLimit	0.6
	StaticPriceBandUpperLimit	0.8
	TotalShares	100
	OwnershipUpperLimit	0.2
	TickSize	1
	LotSize	1
Limit	8	3	6	6	4	SELL	0	---	0
NewOrderRs	Accepted
	Trades	0
	Orders	4
	Order	Limit	2	3	5	4	8	SELL	0	---	0
	Order	Limit	3	3	2	6	7	SELL	0	---	0
	Order	Limit	8	3	6	6	4	SELL	0	---	0
	Order	Limit	6	1	4	9	7	SELL	0	---	0
	Credits	7
	Credit	1	1
	Credit	2	3
	Credit	3	5
	Credit	4	4
	Credit	5	17
	Credit	6	13
	Credit	7	0
	Ownerships	7
	Ownership	1	12
	Ownership	2	58
	Ownership	3	62
	Ownership	4	12
	Ownership	5	31
	Ownership	6	12
	Ownership	7	35
	ReferencePrice	5
	StaticPriceBandLowerLimit	0.6
	StaticPriceBandUpperLimit	0.8
	TotalShares	100
	OwnershipUpperLimit	0.2
	TickSize	1
	LotSize	1
Limit	9	5	1	4	3	SELL	0	FAK	0
NewOrderRs	Eliminated
	Trades	0
	Orders	4
	Order	Limit	2	3	5	4	8	SELL	0	---	0
	Order	Limit	3	3	2	6	7	SELL	0	---	0
	Order	Limit	8	3	6	6	4	SELL	0	---	0
	Order	Limit	6	1	4	9	7	SELL	0	---	0
	Credits	7
	Credit	1	1
	Credit	2	3
	Credit	3	5
	Credit	4	4
	Credit	5	17
	Credit	6	13
	Credit	7	0
	Ownerships	7
	Ownership	1	12
	Ownership	2	58
	Ownership	3	62
	Ownership	4	12
	Ownership	5	31
	Ownership	6	12
	Ownership	7	35
	ReferencePrice	5
	StaticPriceBandLowerLimit	0.6
	StaticPriceBandUpperLimit	0.8
	TotalShares	100
	OwnershipUpperLimit	0.2
	TickSize	1
	LotSize	1
Limit	10	5	1	4	8	SELL	5	---	0
ReplaceOrderRs	Rejected
	Trades	0
	Orders	4
	Order	Limit	2	3	5	4	8	SELL	0	---	0
	Order	Limit	3	3	2	6	7	SELL	0	---	0
	Order	Limit	8	3	6	6	4	SELL	0	---	0
	Order	Limit	6	1	4	9	7	SELL	0	---	0
	Credits	7
	Credit	1	1
	Credit	2	3
	Credit	3	5
	Credit	4	4
	Credit	5	17
	Credit	6	13
	Credit	7	0
	Ownerships	7
	Ownership	1	12
	Ownership	2	58
	Ownership	3	62
	Ownership	4	12
	Ownership	5	31
	Ownership	6	12
	Ownership	7	35
	ReferencePrice	5
	StaticPriceBandLowerLimit	0.6
	StaticPriceBandUpperLimit	0.8
	TotalShares	100
	OwnershipUpperLimit	0.2
	TickSize	1
	LotSize	1
Iceberg	11	1	4	9	7	BUY 	1	---	0
NewOrderRs	Rejected
	Trades	0
	Orders	4
	Order	Limit	2	3	5	4	8	SELL	0	---	0
	Order	Limit	3	3	2	6	7	SELL	0	---	0
	Order	Limit	8	3	6	6	4	SELL	0	---	0
	Order	Limit	6	1	4	9	7	SELL	0	---	0
	Credits	7
	Credit	1	1
	Credit	2	3
	Credit	3	5
	Credit	4	4
	Credit	5	17
	Credit	6	13
	Credit	7	0
	Ownerships	7
	Ownership	1	12
	Ownership	2	58
	Ownership	3	62
	Ownership	4	12
	Ownership	5	31
	Ownership	6	12
	Ownership	7	35
	ReferencePrice	5
	StaticPriceBandLowerLimit	0.6
	StaticPriceBandUpperLimit	0.8
	TotalShares	100
	OwnershipUpperLimit	0.2
	TickSize	1
	LotSize	1
Limit	12	3	4	4	5	BUY 	3	---	0
NewOrderRs	Accepted
	Trades	1
	Trade	4	5	12	2
	Orders	4
	Order	Limit	2	3	5	4	3	SELL	0	---	0
	Order	Limit	3	3	2	6	7	SELL	0	---	0
	Order	Limit	8	3	6	6	4	SELL	0	---	0
	Order	Limit	6	1	4	9	7	SELL	0	---	0
	Credits	7
	Credit	1	1
	Credit	2	3
	Credit	3	5
	Credit	4	4
	Credit	5	17
	Credit	6	13
	Credit	7	0
	Ownerships	7
	Ownership	1	12
	Ownership	2	58
	Ownership	3	62
	Ownership	4	17
	Ownership	5	26
	Ownership	6	12
	Ownership	7	35
	ReferencePrice	5
	StaticPriceBandLowerLimit	0.6
	StaticPriceBandUpperLimit	0.8
	TotalShares	100
	OwnershipUpperLimit	0.2
	TickSize	1
	LotSize	1
Limit	13	5	6	7	1	BUY 	0	---	0
NewOrderRs	Accepted
	Trades	1
	Trade	4	1	13	2
	Orders	4
	Order	Limit	2	3	5	4	2	SELL	0	---	0
	Order	Limit	3	3	2	6	7	SELL	0	---	0
	Order	Limit	8	3	6	6	4	SELL	0	---	0
	Order	Limit	6	1	4	9	7	SELL	0	---	0
	Credits	7
	Credit	1	1
	Credit	2	3
	Credit	3	9
	Credit	4	4
	Credit	5	13
	Credit	6	13
	Credit	7	0
	Ownerships	7
	Ownership	1	12
	Ownership	2	58
	Ownership	3	62
	Ownership	4	17
	Ownership	5	25
	Ownership	6	13
	Ownership	7	35
	ReferencePrice	5
	StaticPriceBandLowerLimit	0.6
	StaticPriceBandUpperLimit	0.8
	TotalShares	100
	OwnershipUpperLimit	0.2
	TickSize	1
	LotSize	1
Limit	14	1	6	7	1	SELL	0	---	0
NewOrderRs	Accepted
	Trades	0
	Orders	5
	Order	Limit	2	3	5	4	2	SELL	0	---	0
	Order	Limit	3	3	2	6	7	SELL	0	---	0
	Order	Limit	8	3	6	6	4	SELL	0	---	0
	Order	Limit	14	1	6	7	1	SELL	0	---	0
	Order	Limit	6	1	4	9	7	SELL	0	---	0
	Credits	7
	Credit	1	1
	Credit	2	3
	Credit	3	9
	Credit	4	4
	Credit	5	13
	Credit	6	13
	Credit	7	0
	Ownerships	7
	Ownership	1	12
	Ownership	2	58
	Ownership	3	62
	Ownership	4	17
	Ownership	5	25
	Ownership	6	13
	Ownership	7	35
	ReferencePrice	5
	StaticPriceBandLowerLimit	0.6
	StaticPriceBandUpperLimit	0.8
	TotalShares	100
	OwnershipUpperLimit	0.2
	TickSize	1
	LotSize	1
CancelOrderRs	Accepted
	Orders	4
	Order	Limit	2	3	5	4	2	SELL	0	---	0
	Order	Limit	3	3	2	6	7	SELL	0	---	0
	Order	Limit	8	3	6	6	4	SELL	0	---	0
	Order	Limit	6	1	4	9	7	SELL	0	---	0
	Credits	7
	Credit	1	1
	Credit	2	3
	Credit	3	9
	Credit	4	4
	Credit	5	13
	Credit	6	13
	Credit	7	0
	Ownerships	7
	Ownership	1	12
	Ownership	2	58
	Ownership	3	62
	Ownership	4	17
	Ownership	5	25
